[2024-09-11T13:36:59.632+0000] {local_task_job_runner.py:120} INFO - ::group::Pre task execution logs
[2024-09-11T13:36:59.959+0000] {taskinstance.py:2076} INFO - Dependencies all met for dep_context=non-requeueable deps ti=<TaskInstance: cryptocurrencies_etl.send_toRedshift_task manual__2024-09-11T13:36:47.247426+00:00 [queued]>
[2024-09-11T13:36:59.976+0000] {taskinstance.py:2076} INFO - Dependencies all met for dep_context=requeueable deps ti=<TaskInstance: cryptocurrencies_etl.send_toRedshift_task manual__2024-09-11T13:36:47.247426+00:00 [queued]>
[2024-09-11T13:36:59.976+0000] {taskinstance.py:2306} INFO - Starting attempt 1 of 2
[2024-09-11T13:37:00.015+0000] {taskinstance.py:2330} INFO - Executing <Task(PythonOperator): send_toRedshift_task> on 2024-09-11 13:36:47.247426+00:00
[2024-09-11T13:37:00.034+0000] {warnings.py:112} WARNING - /home/***/.local/lib/python3.12/site-packages/***/task/task_runner/standard_task_runner.py:61: DeprecationWarning: This process (pid=79) is multi-threaded, use of fork() may lead to deadlocks in the child.
  pid = os.fork()

[2024-09-11T13:37:00.044+0000] {standard_task_runner.py:63} INFO - Started process 90 to run task
[2024-09-11T13:37:00.049+0000] {standard_task_runner.py:90} INFO - Running: ['***', 'tasks', 'run', 'cryptocurrencies_etl', 'send_toRedshift_task', 'manual__2024-09-11T13:36:47.247426+00:00', '--job-id', '7', '--raw', '--subdir', 'DAGS_FOLDER/dag_etl.py', '--cfg-path', '/tmp/tmp9dqqmwxo']
[2024-09-11T13:37:00.052+0000] {standard_task_runner.py:91} INFO - Job 7: Subtask send_toRedshift_task
[2024-09-11T13:37:00.115+0000] {task_command.py:426} INFO - Running <TaskInstance: cryptocurrencies_etl.send_toRedshift_task manual__2024-09-11T13:36:47.247426+00:00 [running]> on host 44e7a3c0e0e8
[2024-09-11T13:37:00.349+0000] {taskinstance.py:2648} INFO - Exporting env vars: AIRFLOW_CTX_DAG_OWNER='***' AIRFLOW_CTX_DAG_ID='cryptocurrencies_etl' AIRFLOW_CTX_TASK_ID='send_toRedshift_task' AIRFLOW_CTX_EXECUTION_DATE='2024-09-11T13:36:47.247426+00:00' AIRFLOW_CTX_TRY_NUMBER='1' AIRFLOW_CTX_DAG_RUN_ID='manual__2024-09-11T13:36:47.247426+00:00'
[2024-09-11T13:37:00.350+0000] {taskinstance.py:430} INFO - ::endgroup::
[2024-09-11T13:37:01.033+0000] {logging_mixin.py:188} INFO - DataFrame types:
[2024-09-11T13:37:01.035+0000] {logging_mixin.py:188} INFO - id             int64
name          object
symbol        object
marketcap    float64
price        float64
volume_24    float64
dtype: object
[2024-09-11T13:37:01.353+0000] {logging_mixin.py:188} INFO - Table gianni_ev93_coderhouse.coinmarketcap is ready
[2024-09-11T13:37:01.354+0000] {logging_mixin.py:188} INFO - Insert query:
[2024-09-11T13:37:01.354+0000] {logging_mixin.py:188} INFO - INSERT INTO gianni_ev93_coderhouse.coinmarketcap (name, symbol, marketcap, price, volume_24) VALUES (%s, %s, %s, %s, %s)
[2024-09-11T13:37:16.758+0000] {toRedshift.py:80} ERROR - Error al insertar datos: numeric value "17848183163" out of range for integer

[2024-09-11T13:37:16.759+0000] {taskinstance.py:441} INFO - ::group::Post task execution logs
[2024-09-11T13:37:16.760+0000] {taskinstance.py:2905} ERROR - Task failed with exception
Traceback (most recent call last):
  File "/home/airflow/.local/lib/python3.12/site-packages/airflow/models/taskinstance.py", line 465, in _execute_task
    result = _execute_callable(context=context, **execute_callable_kwargs)
             ^^^^^^^^^^^^^^^^^^^^^^^^^^^^^^^^^^^^^^^^^^^^^^^^^^^^^^^^^^^^^
  File "/home/airflow/.local/lib/python3.12/site-packages/airflow/models/taskinstance.py", line 432, in _execute_callable
    return execute_callable(context=context, **execute_callable_kwargs)
           ^^^^^^^^^^^^^^^^^^^^^^^^^^^^^^^^^^^^^^^^^^^^^^^^^^^^^^^^^^^^
  File "/home/airflow/.local/lib/python3.12/site-packages/airflow/models/baseoperator.py", line 401, in wrapper
    return func(self, *args, **kwargs)
           ^^^^^^^^^^^^^^^^^^^^^^^^^^^
  File "/home/airflow/.local/lib/python3.12/site-packages/airflow/operators/python.py", line 235, in execute
    return_value = self.execute_callable()
                   ^^^^^^^^^^^^^^^^^^^^^^^
  File "/home/airflow/.local/lib/python3.12/site-packages/airflow/operators/python.py", line 252, in execute_callable
    return self.python_callable(*self.op_args, **self.op_kwargs)
           ^^^^^^^^^^^^^^^^^^^^^^^^^^^^^^^^^^^^^^^^^^^^^^^^^^^^^
  File "/opt/airflow/dags/modules/toRedshift.py", line 76, in send_toRedshift_task
    cursor.executemany(insert_query, df[['name', 'symbol', 'marketcap', 'price', 'volume_24']].values.tolist())
psycopg2.errors.NumericValueOutOfRange: numeric value "17848183163" out of range for integer

[2024-09-11T13:37:16.771+0000] {taskinstance.py:1206} INFO - Marking task as UP_FOR_RETRY. dag_id=cryptocurrencies_etl, task_id=send_toRedshift_task, run_id=manual__2024-09-11T13:36:47.247426+00:00, execution_date=20240911T133647, start_date=20240911T133659, end_date=20240911T133716
[2024-09-11T13:37:16.788+0000] {standard_task_runner.py:110} ERROR - Failed to execute job 7 for task send_toRedshift_task (numeric value "17848183163" out of range for integer
; 90)
[2024-09-11T13:37:16.810+0000] {local_task_job_runner.py:240} INFO - Task exited with return code 1
[2024-09-11T13:37:16.829+0000] {taskinstance.py:3503} INFO - 0 downstream tasks scheduled from follow-on schedule check
[2024-09-11T13:37:16.844+0000] {local_task_job_runner.py:222} INFO - ::endgroup::
